{
    "type": "bundle",
    "id": "bundle--2704d6b9-0ba3-49d2-841c-927144dfe7ea",
    "objects": [
        {
            "type": "vulnerability",
            "spec_version": "2.1",
            "id": "vulnerability--6dd205a0-11de-4229-9c2b-942f896fd364",
            "created_by_ref": "identity--8ce3f695-d5a4-4dc8-9e93-a65af453a31a",
            "created": "2025-05-16T00:22:42.967268Z",
            "modified": "2025-05-16T00:22:42.967268Z",
            "name": "CVE-2025-4516",
            "description": "There is an issue in CPython when using `bytes.decode(\"unicode_escape\", error=\"ignore|replace\")`. If you are not using the \"unicode_escape\" encoding or an error handler your usage is not affected. To work-around this issue you may stop using the error= handler and instead wrap the bytes.decode() call in a try-except catching the DecodeError.",
            "external_references": [
                {
                    "source_name": "cve",
                    "external_id": "CVE-2025-4516"
                }
            ]
        }
    ]
}